Workbook

Sheet Abbreviations
A1: שם בערבית | B1: שם בתעתיק | C1: קיצור
A2: أبو سنان | B2: Abu Snān | C2: ASn
A3: أبو غوش | B3: Abu Ġoš | C3: AĠ
A4: إرطاس | B4: Irṭās | C4: Ir
A5: إرطاس | B5: Irṭās | C5: Ir
A6: إعبلين | B6: ʿIbillīn | C6: Ib
A7: إكسال | B7: Iksāl | C7: Ik
A8: اريحا | B8: Arīḥa | C8: Arḥ
A9: البعنة | B9: liBʿēni | C9: Bni
A10: البقيعة | B10: ilBqēʿa | C10: Bq
A11: البياضة | B11: elBayāḏ̣a | C11: By
A12: التعامرة | B12: itTaʿāmra | C12: Tʿm
... A193: يطا | B193: Yaṭṭa | C193: Yṭ

Sheet Recordings
B1: שם יישוב בתעתיק | C1: שם יישוב/שבט | D1: קוד ישוב/שבט | E1: קהילה | F1: קוד קהילה | G1: מיון גס לתתי-קבוצות | H1: שם דובר | I1: מגדר דובר | J1: מס' קטלוגי לדובר | K1: תוכן ההקלטה | L1: תופעות בהקלטה | M1: aCC>iCC | N1: diphthongs | O1: fem. ending | P1: med. Imāla | Q1: -a+n (Aram. sub.) | R1: pausal -u>-o#, -i>-e# | S1: ج | T1: ق | U1: assimilation of gutturals to the left | V1: vowel epenthesis | W1: vocal harmonizing | X1: lowering of -uC>-oC/-iC>-eC | Y1: independent pronoun 1.pl نحن | Z1: independent pronoun 3.pl (هم) | AA1: 2.m.pl pron. كم- | AB1: 3.m.pl (poss. pro) هم- | AC1: 3.f.sg pron. ها- | AD1: impf. prefix 3.m.sg | AE1: "want" | AF1: "now" | AG1: "when?" | AH1: "here" | AI1: "was" | AJ1: הערות | AK1: ייעוד | AL1: סטטוס | AM1: בטיפול של | AN1: קישורים להקלטות | AO1: משך ההקלטה | AP1: שם מקליט | AQ1: זמן ההקלטה | AR1: קישורים לתעתיקים | AS1: האם קיים ברשימת היישובים?
A2: مجدل شمس | B2: Maždal Šams | C2: Maždal Šams | D2: MŠ | E2: Druze (Golan) | F2: D | G2: ṯqīl | I2: F | J2: MŠ.1FD | K2: ריכולים וקשקושים. יש קצת סיפורים אחרי סביב 08:00. (יש רעשי רקע לאורך ההקלטה). | L2: dipthongs: nawm 11:56, bayḏ̣āt 27;05; interdentals: xuḏ̣ra 00:55, ; med. imāla: kibēb 01:00, kēn 01:14, banētu 02:38, mētat 04:21; 3.m.pl (poss. pro) هم-: ʿindun 01:01; "was": kēn 01:14; 3.f.sg pron. ها-: kulla 15:01; | M2: FALSE | N2: TRUE | O2: -i | P2: TRUE | Q2: FALSE | R2: TRUE | S2: ž | T2: q | U2: FALSE | W2: FALSE | X2: FALSE | Y2: niḥna | AB2: -h- > -∅- (e.g. -on) | AC2: -a / -ya (after -i-) | AE2: badd | AF2: issa/hassāʿa | AG2: ēmta | AI2: kān | AJ2: תעתיק 25:52-28:50 | AK2: תעתיק | AN2: MŠ.1FD.R1 | AO2: 0.026122685 | AR2: - | AS2: =NOT(ISERROR(MATCH(A2,'Villages according to موسوعة ال'!C:C,0))) -> TRUE
A3: مجدل شمس | B3: Maždal Šams | F3: D | K3: המלחמה בסוריה | L3: med. imāla: mawēdd 01:00, bitnēm 00:39, nēymi 01:42; 1st.personal pron.: ani 00:32; u>i vowel shift: alqids 00:32, kill 01:55, bikra 01:59; | M3: FALSE | N3: TRUE | O3: -i | P3: TRUE | Q3: FALSE | R3: TRUE | S3: ž | T3: q | U3: FALSE | W3: FALSE | X3: FALSE | Y3: niḥna | AC3: -a / -ya (after -i-) | AI3: kān | AK3: דקדוק | AN3: MŠ.1FD.R2 | AO3: 0.0073842593 | AR3: - | AS3: =NOT(ISERROR(MATCH(A3,'Villages according to موسوعة ال'!C:C,0))) -> TRUE
A4: عين قنية | B4: Ein Qiniyye | C4: Ein Qiniyye | D4: EQ | E4: Druze (Golan) | F4: D | G4: ṯqīl | I4: M | J4: EQ.1MD | K4: סיפור עם על מלך | L4: phonotactictical syll. org.: silsilit mayy 00:55; med. imāla: hēḏa lmalak 00:05. no assimilation of gutturals to the left: yrūḥ ʿala 00:08; diphthongs: ṣayd 00:08; | M4: FALSE | N4: TRUE | O4: -i | P4: TRUE | Q4: FALSE | R4: FALSE | S4: ž | T4: q | U4: FALSE | W4: FALSE | X4: FALSE | AE4: badd | AF4: issa/hassāʿa | AK4: תעתיק | AN4: EQ.1MD.R1 | AO4: 0.0021990741 | AR4: - | AS4: =NOT(ISERROR(MATCH(A4,'Villages according to موسوعة ال'!C:C,0))) -> TRUE
A5: مسعدة | B5: Masʿadi | C5: Masʿadi | D5: Ms | E5: Druze (Golan) | F5: D | H5: Maysūn Wēli | I5: F | J5: Ms.1FD | M5: FALSE | N5: FALSE | P5: FALSE | Q5: FALSE | R5: FALSE | U5: FALSE | W5: FALSE | X5: FALSE | AN5: Ms.1FD.R1 | AO5: 0.049490741 | AR5: - | AS5: =NOT(ISERROR(MATCH(A5,'Villages according to موسوعة ال'!C:C,0))) -> TRUE
A6: مسعدة | B6: Masʿadi | E6: Druze (Golan) | F6: D | G6: ṯqīl | H6: Tamāra lḤalabi | I6: F | J6: Ms.2FD | M6: FALSE | N6: FALSE | P6: FALSE | Q6: FALSE | R6: FALSE | U6: FALSE | W6: FALSE | X6: FALSE | AK6: דקדוק | AN6: Ms.2FD.R1 | AO6: 0.0071875 | AP6: Nancy Yonatan Yakir | AR6: - | AS6: =NOT(ISERROR(MATCH(A6,'Villages according to موسوعة ال'!C:C,0))) -> TRUE
A7: مسعدة | B7: Masʿadi | F7: D | K7: לאחר שלא קיבלו חופשה מביה"ס היא וחבריה ברחו ממנו | L7: fe. ending: munēsabi 00:08, miš mitḏakkri 00:09;med. imāla: ṯēmin 00:03, kēn 00:05, munēsabi 00:08; pausal -u > -o#, -i > -e#: rāseː# 00:55; | M7: FALSE | N7: FALSE | O7: -i | P7: TRUE | Q7: FALSE | R7: TRUE | S7: ž | T7: q | U7: FALSE | W7: FALSE | X7: FALSE | Z7: hinne/hinne | AK7: תעתיק | AN7: Ms.2FD.R2 | AO7: 0.0011226852 | AP7: Nancy Yonatan Yakir | AR7: - | AS7: =NOT(ISERROR(MATCH(A7,'Villages according to موسوعة ال'!C:C,0))) -> TRUE
A8: مسعدة | B8: Masʿadi | F8: D | M8: FALSE | N8: FALSE | P8: FALSE | Q8: FALSE | R8: FALSE | U8: FALSE | W8: FALSE | X8: FALSE | AK8: דקדוק | AN8: Ms.2FD.R3 | AO8: 0.0049884259 | AP8: Nancy Yonatan Yakir | AR8: - | AS8: =NOT(ISERROR(MATCH(A8,'Villages according to موسوعة ال'!C:C,0))) -> TRUE
A9: غجر | B9: Ġaǧar | C9: Ġaǧar | D9: Ġǧ | E9: Alawite | F9: Al | I9: F | J9: Ġǧ.1F | K9: יש הרבה רעשי רקע ולא מעט דיבור בעברית. שתי דוברות (?). אחת מספרת קצת על חייה, חתונות בכפר, בישול. | L9: aCC => iCC: ihli 01:09 [cf. maḥabbe 01:59], ; negation: mu mnīḥ 01:24, imp. prefix 1 sg. bi-: bištiġil 04:38, vocal harmony: xibiz 07:38, 3 f.sg. perf. ending -et: ḥamlet 08:13, nāmet 08:16, fāʾet 08:17, žābet 08:35 [cf. rāḥat 08:13]; medial imāla: ʿēmla [cf. rāḥat 08:13], sandhi syncope: mart xayyi 08:36. | M9: TRUE | N9: FALSE | O9: -e | P9: FALSE | Q9: FALSE | R9: TRUE | S9: ž | U9: FALSE | W9: FALSE | X9: FALSE | AJ9: נטיית גוף נסתרת בעבר בין 08:05-08:35 | AK9: דקדוק | AN9: Gǧ.1F.R1 | AO9: 0.0063194444 | AR9: - | AS9: =NOT(ISERROR(MATCH(A9,'Villages according to موسوعة ال'!C:C,0))) -> TRUE
A10: غجر | B10: Ġaǧar | F10: Al | K10: אוכל ובישול. | L10: "זיתים" zaytūn (דיפתונג). | M10: FALSE | N10: FALSE | P10: FALSE | Q10: FALSE | R10: FALSE | U10: FALSE | W10: FALSE | X10: FALSE | AK10: זבל | AN10: Gǧ.1F.R2 | AO10: 0.00078703704 | AR10: - | AS10: =NOT(ISERROR(MATCH(A10,'Villages according to موسوعة ال'!C:C,0))) -> TRUE
A11: غجر | B11: Ġaǧar | F11: Al | K11: הצאן והבקר בכפר יודעים לחזור לבד מהמרעה, כל ראש לביתו | L11: 3 f.sg. perf. ending -et: ḍallet 02:12; medial imāla: tēni 03:10 [cf. muʾāmale 02:59, bil*ā*i ḥālo 04:20, sahrāt 04:46, ḥaflāt 04:46, mašākil 05:04]; indep. pron. 1 pl.: niḥna 04:56; dipthongs: zaytūn 11:25; vocal harmony: xibiz 11:36; aCC=> iCC: miġrib 05:59. | M11: FALSE | N11: FALSE | O11: -i | P11: TRUE | Q11: FALSE | R11: TRUE | S11: ž | T11: ʾ | U11: FALSE | W11: FALSE | X11: FALSE | Y11: iḥna | AC11: -ha | AE11: badd | AF11: issa/hassāʿa | AI11: kān / čān | AJ11: תעתיק בין 05:45-07:37. לדלג על הערות מראיינים באמצע. | AK11: תעתיק | AL11: אושר (אורי) | AM11: בן | AN11: Ġǧ.1F.R3 | AO11: 0.0090277778 | AR11: Ġǧ.1F.R3(t) | AS11: =NOT(ISERROR(MATCH(A11,'Villages according to موسوعة ال'!C:C,0))) -> TRUE
A12: غجر | B12: Ġaǧar | F12: Al | K12: קשה לשמוע בגלל האיכות. | L12: medial imāla: [cf. māt 02:28, šabāb 03:35]; 3 f.sg. perf. ending -et: ištaġlet 02:48; indep. pron. 1 pl.: niḥna 04:00 | M12: FALSE | N12: FALSE | O12: -e | P12: FALSE | Q12: FALSE | R12: TRUE | S12: ž | U12: FALSE | W12: FALSE | X12: FALSE | Y12: niḥna | AE12: badd | AF12: issa/hassāʿa | AK12: זבל | AN12: Gǧ.1F.R4 | AO12: 0.0046643519 | AR12: - | AS12: =NOT(ISERROR(MATCH(A12,'Villages according to موسوعة ال'!C:C,0))) -> TRUE
A13: غجر | B13: Ġaǧar | F13: Al | I13: F | J13: Ġǧ.2F | K13: אירוסין וחתונה | L13: aCC=> iCC: ʿihlo: 01:10, 01:14, 01:16, 03:04, 05:07, 05:16, 06:12 [cf. ḥēki la-ʾahlo 01:12, ḥatta 01:24], dibke/diḥke 05:33; med. imāla: ḥēki 01:12, ē 01:45, ktēb 03:07, bišērku 03:23, tēni 03:28 [cf. bināsíbna 01:28]; Clusters: sinisle 02:00, bikitbu 03:06; dipthongs: ʿayle 00:58 01:19 [cf. bēt 02:18, yōm 06:10] | M13: TRUE | N13: TRUE | O13: -i | P13: TRUE | Q13: FALSE | R13: TRUE | S13: ž | T13: ʾ | U13: FALSE | V13: *CCC > CvCC | W13: FALSE | X13: FALSE | Y13: iḥna | AD13: bi- | AE13: badd | AF13: issa/hassāʿa | AH13: hōn | AJ13: תעתיק בין 00:31 - 03:27 | AK13: תעתיק | AL13: אושר (אורי) | AM13: בן | AN13: Ġǧ.2F.R1 | AO13: 0.0074074074 | AR13: Ġǧ.2F.R1(t) | AS13: =NOT(ISERROR(MATCH(A13,'Villages according to موسوعة ال'!C:C,0))) -> TRUE
A14: الجش | B14: ižŽišš | C14: ižŽišš | D14: Žš | E14: Christian (Catholic) | F14: C | G14: tʾīl | H14: אבו כמיל (AK) | I14: M | J14: Žš.1MC | K14: מספר על חיפושיו אחר אישה לאחר שהתאלמן. | L14: אין בין-שיניות. מימוש ج>ž. מימוש ق>ʾ. צורת baddi., כינוי נסתרת ללא h. אין בין-שיניות. | M14: FALSE | N14: FALSE | O14: -i | P14: FALSE | Q14: FALSE | R14: FALSE | S14: ž | U14: FALSE | W14: FALSE | X14: FALSE | AB14: -h- > -∅- (e.g. -on) | AD14: bi- | AE14: badd | AF14: issa/hassāʿa | AK14: הגהה | AL14: עבר הגהה | AM14: נור + עהוד | AN14: Žš.1MC.R1 | AO14: 0.0014236111 | AP14: Rajaa | AQ14: 2017 (??) | AR14: Žš.1MC.R1(t) | AS14: =NOT(ISERROR(MATCH(A14,'Villages according to موسوعة ال'!C:C,0))) -> TRUE
A15: كفر برعم | B15: Kufur Birʿim | C15: Kufur Birʿim | D15: Br | E15: Christian (Maronite) | F15: C | G15: tʾīl | H15: Suʿād Antanas | I15: F | J15: Br.1FC | K15: על המשפחה. יש לה שלוש בנות ושני בנים, בת אחת למדה ומלמדת כימיה, אחת למדה חינוך מיוחד, אחת עניינים חברתיים. בן אחד עובד ברמב"ם והשני עובד במחשבים. | L15: ʿandi. אין בין-שיניות. סיומת נקבה i-. | M15: FALSE | N15: FALSE | O15: -i | P15: FALSE | Q15: FALSE | R15: FALSE | S15: ž | U15: FALSE | W15: FALSE | X15: FALSE | AD15: bi- | AE15: bidd | AF15: issa/hassāʿa | AH15: hōn | AK15: הגהה | AL15: עבר הגהה | AM15: נור + עהוד | AN15: Br.1FC.R1 | AO15: 0.0011458333 | AP15: Rajaa | AQ15: 2017 | AR15: Br.1FC.R1(t) | AS15: =NOT(ISERROR(MATCH(A15,'Villages according to موسوعة ال'!C:C,0))) -> TRUE
A16: كفر برعم | B16: Kufur Birʿim | E16: Christian (Maronite) | F16: C | G16: tʾīl | H16: Žiryis Qayṣar Antanas | I16: M | J16: Br.2MC | K16: למד בבית ספר יהודי ולא ידע עברית. ביום הראשון אבא שלו אמר שיחכה לו ובסוף הלימודים הוא לא מצא אותו. | L16: "הלכתי" נשמע כמו ruḥet>raḥet*. כינוי חבור נסתרת ללא h, למשל: bi-waʾta. אין בין-שיניות. ق = q. ج = ž. תנועת a בעתיד ב-aʿraf אבל yiʿrif . | M16: FALSE | N16: FALSE | P16: FALSE | Q16: FALSE | R16: FALSE | U16: FALSE | W16: FALSE | X16: FALSE | AK16: בקרה | AL16: אושר (אורי) | AM16: נור + עהוד | AN16: Br.2MC.R1 | AO16: 0.0016782407 | AP16: Elisheva | AQ16: 2016 | AR16: Br.2MC.R1(t) | AS16: =NOT(ISERROR(MATCH(A16,'Villages according to موسوعة ال'!C:C,0))) -> TRUE
A17: كفر برعم | B17: Kufur Birʿim | E17: Christian (Maronite) | F17: C | H17: Antanas Marūn | I17: M | J17: Br.3MC | K17: מספר על בנו שנהרג בתאונה בגלל התקף לב. הותיר לו שלוש נכדות. | L17: סיומת נקבה i-. אמאלה תוכית עדינה. ʿandīhum | M17: FALSE | N17: FALSE | P17: FALSE | Q17: FALSE | R17: FALSE | U17: FALSE | W17: FALSE | X17: FALSE | AK17: דקדוק | AN17: Br.3MC.R1 | AO17: 0.0013541667 | AR17: - | AS17: =NOT(ISERROR(MATCH(A17,'Villages according to موسوعة ال'!C:C,0))) -> TRUE
A18: كفر برعم | B18: Kufur Birʿim | E18: Christian (Maronite) | F18: C | H18: Saʿda Antanas Faraḥ Marūn | I18: F | J18: Br.4FC | K18: התחתנה עם מישהו ממשפחת ח'ורי שהיה חבר של אביה. היא קטנה ממנו ב-10 שנים. הוריו גרו איתם ואחיו היה בלבנון. | M18: FALSE | N18: FALSE | P18: FALSE | Q18: FALSE | R18: FALSE | U18: FALSE | W18: FALSE | X18: FALSE | AK18: דקדוק | AN18: Br.4FC.R1 | AO18: 0.0009375 | AR18: - | AS18: =NOT(ISERROR(MATCH(A18,'Villages according to موسوعة ال'!C:C,0))) -> TRUE
A19: كفر برعم | B19: Kufur Birʿim | E19: Christian (Maronite) | F19: C | G19: tʾīl | H19: Ṣubḥi Farḥāt | I19: M | J19: Br.5MC | K19: התקפה על המנזר (או דיר חנא?). | M19: FALSE | N19: FALSE | P19: FALSE | Q19: FALSE | R19: FALSE | U19: FALSE | W19: FALSE | X19: FALSE | AK19: תעתיק | AL19: עבר תעתיק | AM19: דאליה + אורי | AN19: Br.5MC.R1 | AO19: 0.0020601852 | AR19: Br.5MC.R1(t) | AS19: =NOT(ISERROR(MATCH(A19,'Villages according to موسوعة ال'!C:C,0))) -> TRUE
A20: فسوطة | B20: Fassūṭa | C20: Fassūṭa | D20: Fs | E20: Christian (Catholic) | F20: C | G20: tʾīl | H20: עבלה אבו סים... (AAS) | I20: F | J20: Fs.1FC | K20: הדוד היה סתת שעשה הכול. עבדה אצל הדוד בבניה ותוך כדי הביאה ילדים. | L20: אין בין-שיניות. מימוש ج>ž. מימוש ق>ʾ. שימוש בשורש بقي. סיומת נקבה = i. | M20: FALSE | N20: FALSE | O20: -i | P20: FALSE | Q20: FALSE | R20: FALSE | S20: ž | U20: FALSE | W20: FALSE | X20: FALSE | Y20: iḥna | AB20: -h- > -∅- (e.g. -on) | AD20: bi- | AE20: badd | AF20: issa/hassāʿa | AH20: hōn | AK20: הגהה | AL20: עבר הגהה | AM20: נור + עהוד | AN20: Fs.1FC.R1 | AO20: 0.0022106481 | AP20: Rajaa | AQ20: 2017 (??) | AR20: Fs.1FC.R1(t) | AS20: =NOT(ISERROR(MATCH(A20,'Villages according to موسوعة ال'!C:C,0))) -> TRUE
A21: فسوطة | B21: Fassūṭa | F21: C | K21: מתכון לכובה. | M21: FALSE | N21: FALSE | P21: FALSE | Q21: FALSE | R21: FALSE | U21: FALSE | W21: FALSE | X21: FALSE | AK21: דקדוק | AN21: Fs.1FC.R2 | AO21: 0.0012847222 | AP21: Rajaa | AQ21: 2017 (??) | AR21: - | AS21: =NOT(ISERROR(MATCH(A21,'Villages according to موسوعة ال'!C:C,0))) -> TRUE
A22: فسوطة | B22: Fassūṭa | E22: Christian (Catholic) | F22: C | G22: tʾīl | H22: מרסיל אבו-איוב (MAA) | I22: F | J22: Fs.2FC | K22: חוויות מביה"ח. | L22: אין בין-שיניות. מימוש ج>ž. מימוש ق>ʾ. סיומת נקבה = i. אין h בכינוי חבור. שימוש בגלייד בכינוי חבור: fiyyu. | M22: FALSE | N22: FALSE | O22: -i | P22: FALSE | Q22: FALSE | R22: TRUE | S22: ž | T22: ʾ | U22: FALSE | W22: FALSE | X22: TRUE | AB22: -h- > -∅- (e.g. -on) | AD22: bi- | AF22: issa/hassāʿa | AH22: hōn | AI22: kān / čān | AK22: הגהה | AL22: עבר הגהה | AM22: נור + עהוד | AN22: Fs.2FC.R1 | AO22: 0.00081018519 | AP22: Rajaa | AQ22: 43070 | AR22: Fs.2FC.R1(t) | AS22: =NOT(ISERROR(MATCH(A22,'Villages according to موسوعة ال'!C:C,0))) -> TRUE
A23: فسوطة | B23: Fassūṭa | E23: Christian (Catholic) | F23: C | G23: tʾīl | H23: מריס ח'ליל נז'אר (MXN) | I23: M | J23: Fs.3MC | K23: מספר שאמו הגיע לכפר מסוריה כמורה ואביו עזב את ארוסתו בשביל להתחתן איתה. | L23: כינוי חבור נקבה בלי h. לפעמים יש בין-שיניות ולפעמים לא. | M23: FALSE | N23: FALSE | O23: -i | P23: FALSE | Q23: FALSE | R23: FALSE | S23: ž | T23: ʾ | U23: FALSE | W23: TRUE | X23: FALSE | AC23: -a | AD23: bi- | AF23: issa/hassāʿa | AH23: hōn | AI23: kān / čān | AK23: הגהה | AL23: אושר (אורי) | AM23: נור + עהוד | AN23: Fs.3MC.R1 | AO23: 0.00048611111 | AP23: Layal Bshara | AQ23: 43070 | AR23: Fs.3MC.R1(t) | AS23: =NOT(ISERROR(MATCH(A23,'Villages according to موسوعة ال'!C:C,0))) -> TRUE
A24: فسوطة | B24: Fassūṭa | F24: C | K24: מספר על אמו שהגיעה מיברוד, סוריה, ועל החיים שם. | L24: כינוי חבור "הם" an-, בצורה benātan. סיומת נקבה i-. | M24: FALSE | N24: FALSE | O24: -i | P24: FALSE | Q24: FALSE | R24: FALSE | S24: ž | T24: ʾ | U24: FALSE | W24: FALSE | X24: FALSE | AB24: -h- > -∅- (e.g. -on) | AC24: -a | AD24: bi- | AF24: issa/hassāʿa | AH24: hōn | AI24: kān / čān | AJ24: לחבר לטקסט הקודם של אותו הדובר | AK24: הגהה | AL24: אושר (אורי) | AM24: נור + עהוד | AN24: Fs.3MC.R2 | AO24: 0.00061342593 | AP24: Layal Bshara | AQ24: 43071 | AR24: Fs.3MC.R2(t) | AS24: =NOT(ISERROR(MATCH(A24,'Villages according to موسوعة ال'!C:C,0))) -> TRUE
A25: ترشيحا | B25: Taršīḥa | C25: Taršīḥa | D25: Tr | E25: Christian (Maronite) | F25: C | G25: tʾīl | I25: F | J25: Tr.1F | K25: הדוברת מספרת על הילדות, משחקים, רקמה. | L25: šū usmo, כינוי חבור נקבה בלי h בצורה kullayāta. حتّى = ḥitta, ج = לפעמים ǧ (בצורות ǧīl, nǧīb) אך לפעמים ž (בצורות fanažīn, ḥižāra, žirān, žīl). ق = ʾ. | M25: FALSE | N25: FALSE | P25: FALSE | Q25: FALSE | R25: FALSE | U25: FALSE | W25: FALSE | X25: FALSE | AK25: תעתיק | AL25: אושר (אורי) | AM25: ניצן + תסנים | AN25: Tr.1F.R1 | AO25: 0.0016898148 | AR25: Tr.1F.R1(t) | AS25: =NOT(ISERROR(MATCH(A25,'Villages according to موسوعة ال'!C:C,0))) -> TRUE
A26: ترشيحا | B26: Taršīḥa | E26: Christian (Maronite) | F26: C | G26: tʾīl | H26: Sitt Jarāysi | I26: F | J26: Tr.2F | K26: סיפור על סוס שהיה למשפחתתה . | L26: אמאלה תוכית, baddi. ق = ʾ. ج>ž. קיצור דיפתונג: žaʿān. אין בינן-שיניות. בכינוי החבור נקבה יש h. | M26: FALSE | N26: FALSE | O26: -i | P26: FALSE | Q26: FALSE | R26: FALSE | S26: ž | T26: ʾ | U26: FALSE | W26: TRUE | X26: FALSE | Y26: iḥna | AA26: -ku/-ko | AC26: -ha | AE26: badd | AI26: kān / čān | AK26: הגהה | AL26: אושר (אורי) | AM26: בן | AN26: Tr.2F.R1 | AO26: 0.0014699074 | AP26: Maram Jaraysi | AR26: Tr.2F.R1(t) | AS26: =NOT(ISERROR(MATCH(A26,'Villages according to موسوعة ال'!C:C,0))) -> TRUE
A27: ترشيحا | B27: Taršīḥa | E27: Christian (Maronite) | F27: C | L27: סובסרט ארמי: lamman. אין בין-שיניות. אמאלה סופית i-. מימוש ج>ž. מימוש ق>ʾ. איבוד נחציות tisfīr. אמאלה תוכית עדינה. ḍarabtu la-hāda lwalad | M27: TRUE | N27: FALSE | O27: -i | P27: TRUE | Q27: TRUE | R27: FALSE | S27: ž | T27: ʾ | U27: TRUE | W27: TRUE | X27: FALSE | Y27: iḥna | AD27: bi- | AF27: issa/hassāʿa | AI27: kān / čān | AK27: הגהה | AL27: עבר הגהה | AM27: בן | AN27: Tr.2F.R2 | AO27: 0.0033101852 | AP27: Maram Jaraysi | AR27: Tr.2F.R2(t) | AS27: =NOT(ISERROR(MATCH(A27,'Villages according to موسوعة ال'!C:C,0))) -> TRUE
A28: ترشيحا | B28: Taršīḥa | E28: Christian (Maronite) | F28: C | K28: מספרת על משפחתה ועל חייה. | L28: סיומת נקבה i-. הנמכת ססב"מ, סיומת הפועל perf.1SG היא et-. "בנים" ṣibyān. אין בין-שיניות. צורת הפועל perf.3SGF היא kibrat. "כולן" kullayāton. "אצלן" ʿandon. "בריאות" ṣuḥḥa. | M28: FALSE | N28: FALSE | P28: FALSE | Q28: FALSE | R28: FALSE | U28: FALSE | W28: FALSE | X28: FALSE | AK28: דקדוק | AN28: Tr.2F.R3 | AO28: 0.0015972222 | AR28: - | AS28: =NOT(ISERROR(MATCH(A28,'Villages according to موسوعة ال'!C:C,0))) -> TRUE
A29: ترشيحا | B29: Taršīḥa | E29: Christian (Maronite) | F29: C | K29: סיפור על בתה של המספרת. | L29: "אמרתי לה" ʾultilla, בלי h בכינוי חבור 3SGF. "את" anti. "ארביץ לך" aḍurbek. "אחיה" axūha עם h בכינוי חבור 3SGF. | M29: FALSE | N29: FALSE | P29: FALSE | Q29: FALSE | R29: FALSE | U29: FALSE | W29: FALSE | X29: FALSE | AC29: -a; -ha only after -ū- | AK29: דקדוק | AN29: Tr.2F.R4 | AO29: 0.0012037037 | AR29: - | AS29: =NOT(ISERROR(MATCH(A29,'Villages according to موسوعة ال'!C:C,0))) -> TRUE
A30: ترشيحا | B30: Taršīḥa | I30: F | J30: Tr.3F | K30: חווית הדוברת בלימודיה בבאר שבע, רחוק מהבית. | L30: ق = ʾ. ج = ž. אמאלה תוכית בולטת. אין בין-שיניות. סיומת נקבה i-. "מחוץ לבית" barrīt ilbēt. | M30: FALSE | N30: FALSE | P30: FALSE | Q30: FALSE | R30: FALSE | U30: FALSE | W30: FALSE | X30: FALSE | AK30: דקדוק | AN30: Tr.3F.R1 | AO30: 0.0015277778 | AR30: - | AS30: =NOT(ISERROR(MATCH(A30,'Villages according to موسوعة ال'!C:C,0))) -> TRUE
A31: ترشيحا | B31: Taršīḥa | E31: Christian (Catholic) | F31: C | G31: tʾīl | H31: Jadon Yousif Jadon (?) | I31: M | J31: Tr.4MC | K31: אחד התלמידים בכיתה שלו חלה והכיתה אספה כסף בשביל לפנק אותו. אחד המורים התרגז. | L31: aCC > iCC, למשל midrasi. ق = ʾ. במילה "חולה" marīḍ אין בין-שיניות, אולם בצורה baʿḏ̣un יש בין-שיניות. "משתתפים" yištirku. "לבדם" laḥālun. "הם" hunni. | M31: FALSE | N31: FALSE | O31: -i | P31: FALSE | Q31: FALSE | R31: FALSE | S31: ž | T31: ʾ | U31: TRUE | V31: *CCC > CCvC | W31: FALSE | X31: FALSE | Z31: hunne | AB31: -h- > -∅- (e.g. -on) | AD31: bi- | AF31: issa/hassāʿa | AH31: hōn | AI31: kān / čān | AK31: הגהה | AL31: עבר הגהה | AM31: נור + עהוד | AN31: Tr.4MC.R1 | AO31: 0.0010416667 | AP31: Yara Bshara | AQ31: 43009 | AR31: Tr.4MC.R1(t) | AS31: =NOT(ISERROR(MATCH(A31,'Villages according to موسوعة ال'!C:C,0))) -> TRUE
A32: ترشيحا | B32: Taršīḥa | E32: Christian (Catholic) | F32: C | G32: tʾīl | H32: Suʿād Asʿad Musa Bshara | I32: F | J32: Tr.5FC | K32: מספרת על בנה (כנראה) בוטרוס ועל חושו המוסיקלי. | L32: "בשבילם" la-ʾilhun. ق = ʾ. ج = ž. "הוא" huwwe. "יעשה" yaʿmal. "רוצה" baddu. "יוצא" byiṭlaʿ. אין בין-שיניות. "אם" iza. "זה" hāda. "ברור/בולט" ẓāhir. | M32: TRUE | N32: TRUE | O32: -i | P32: FALSE | Q32: FALSE | R32: TRUE | S32: ž | T32: ʾ | U32: FALSE | W32: FALSE | X32: FALSE | AC32: -ha | AD32: byi- | AE32: badd | AF32: issa/hassāʿa | AH32: hōn | AI32: kān / čān | AK32: הגהה | AL32: עבר הגהה | AM32: נור + עהוד | AN32: Tr.5FC.R1 | AO32: 0.001412037 | AP32: Yara Bshara | AQ32: 43009 | AR32: Tr.5FC.R1(t) | AS32: =NOT(ISERROR(MATCH(A32,'Villages according to موسوعة ال'!C:C,0))) -> TRUE
A33: ترشيحا | B33: Taršīḥa | F33: C | K33: המשך הסיפור על בוטרוס. | M33: TRUE | N33: TRUE | O33: -i | P33: FALSE | Q33: FALSE | R33: TRUE | S33: ž | T33: ʾ | U33: TRUE | V33: *CCC > CvCC | W33: FALSE | X33: FALSE | AC33: -ha | AD33: byi- | AE33: badd | AF33: issa/hassāʿa | AH33: hōn | AI33: kān / čān | AK33: הגהה | AL33: עבר הגהה | AM33: נור + עהוד | AN33: Tr.5FC.R2 | AO33: 0.00061342593 | AP33: Yara Bshara | AQ33: 43009 | AR33: Tr.5FC.R2(t) | AS33: =NOT(ISERROR(MATCH(A33,'Villages according to موسوعة ال'!C:C,0))) -> TRUE
A34: ترشيحا | B34: Taršīḥa | E34: Christian (Catholic) | F34: C | G34: tʾīl | H34: Wadīʿa Jiryis Khoury | I34: F | J34: Tr.6FC | K34: הקשיים אחרי פטירת אביה של האינפורמנטית והאחריות לגדל אותם המוטלת עליה אין עכשיו. הדוברת מספרת שנאלצה ללכת ללמוד סיעוד בכפר סבא ואז עבדה בכל מני כפרים. | L34: אין בין-שיניות. ق = ʾ. ج = ž. "היו נותנים לנו" kānu yanṭūna. | M34: FALSE | N34: TRUE | O34: -i | P34: FALSE | Q34: FALSE | R34: FALSE | S34: ž | T34: ʾ | U34: FALSE | V34: *CCC > CvCC | W34: FALSE | X34: FALSE | AB34: -h- > -∅- (e.g. -on) | AE34: badd | AF34: issa/hassāʿa | AH34: hōn | AI34: kān / čān | AK34: הגהה | AL34: אושר (אורי) | AM34: נור + עהוד | AN34: Tr.6FC.R1 | AO34: 0.0018287037 | AP34: Yara Bshara | AQ34: 42887 | AR34: Tr.6FC.R1(t) | AS34: =NOT(ISERROR(MATCH(A34,'Villages according to موسوعة ال'!C:C,0))) -> TRUE
A35: ترشيحا | B35: Taršīḥa | E35: Christian (Catholic) | F35: C | G35: tʾīl | H35: ʿAyda Bshara Susan (?) | I35: F | J35: Tr.7FC | K35: הבן שלה הלך לגור עם דוד שלו שאהב אותו באמריקה, נשאר שם ולא רצה לחזור. | L35: "רוצה" baddo. לא מובן לי אבל נראה חשוב: w-ftēt ʾa ktīr haʾnaʿtu. | M35: FALSE | N35: FALSE | O35: -i | P35: FALSE | Q35: FALSE | R35: FALSE | S35: ž | T35: ʾ | U35: FALSE | V35: *CCC > CvCC | W35: FALSE | X35: FALSE | AA35: -kum/-kom | AD35: bi- | AE35: badd | AF35: issa/hassāʿa | AH35: hōn | AI35: kān / čān | AK35: הגהה | AL35: בטיפול | AM35: נור + עהוד | AN35: Tr.7FC.R1 | AO35: 0.00077546296 | AP35: Yara Bshara | AQ35: 43009 | AR35: Tr.7FC.R1(t) | AS35: =NOT(ISERROR(MATCH(A35,'Villages according to موسوعة ال'!C:C,0))) -> TRUE
A36: ترشيحا | B36: Taršīḥa | E36: Muslim | F36: M | G36: tʾīl | H36: Nažwa ʿUmar | I36: F | J36: Tr.8F | K36: הדוברת היא נז'וה עמר, ילידת לבנון. תמצית: המשפחה חוזרת מלבנון עם משפחת רשיד א-סח'ניני. ילדי המשפחה הופכים להיות אחים שלה להנקה והילדים שלהם מכנים אותה עמתי נז'וה. | L36: סיומת נקבה i-. ق = ʾ. פירוק צרור סופי למרות סונוריות יורדת: ḏ̣areb. ج = ž. כינוי חבור "שלהם" hun-. אין בין-שיניות, פוצצים חוץ מ-ẓurūf. | M36: FALSE | N36: FALSE | P36: FALSE | Q36: FALSE | R36: FALSE | U36: FALSE | W36: FALSE | X36: FALSE | AK36: הגהה | AL36: בטיפול | AM36: תומר | AN36: Tr.8F.R1 | AO36: 0.0028125 | AP36: Layāl Bshara | AQ36: 43040 | AR36: Tr.8F.R1(t) | AS36: =NOT(ISERROR(MATCH(A36,'Villages according to موسوعة ال'!C:C,0))) -> TRUE
A37: ترشيحا | B37: Taršīḥa | E37: Muslim | F37: M | G37: ṯʾīl | H37: Xālid Swiṭāt | I37: M | J37: Tr.9M | K37: הדובר פקיד רפואי בקופ״ח, נרקומן דורש התחייבות שלא מגיעה לו ומאיים עליו. | L37: אין בין-שיניות. ق = ʾ. ج = ž. "היו נותנים לנו" kānu yanṭūna. | M37: FALSE | N37: FALSE | P37: FALSE | Q37: FALSE | R37: FALSE | U37: FALSE | W37: FALSE | X37: FALSE | AK37: הגהה | AL37: עבר הגהה | AM37: תומר | AN37: Tr.9M.R1 | AO37: 0.00077546296 | AP37: Layal Bshara | AQ37: 43040 | AR37: Tr.9M.R1(t) | AS37: =NOT(ISERROR(MATCH(A37,'Villages according to موسوعة ال'!C:C,0))) -> TRUE
A38: ترشيحا | B38: Taršīḥa | E38: Muslim | F38: M | H38: Zaki Abu Hāšim | I38: M | J38: Tr.10M | K38: פעם הכול היה רגוע. החקלאים היו עובדים בקיץ ויושבים בחורף. אז היו חיים חברתיים ולא היו טלוויזיות. | L38: יש בין-שיניות. מימוש ق>ʾ ולפעמים q. | M38: FALSE | N38: FALSE | O38: -i | P38: FALSE | Q38: FALSE | R38: FALSE | U38: FALSE | V38: *CCC > CvCC | W38: FALSE | X38: FALSE | AC38: -ha | AK38: הגהה | AL38: עבר הגהה | AM38: בן | AN38: Tr.10M.R1 | AO38: 0.0027430556 | AP38: Rajaa | AQ38: (??) | AR38: Tr.10M.R1(t) | AS38: =NOT(ISERROR(MATCH(A38,'Villages according to موسوعة ال'!C:C,0))) -> TRUE
A39: ترشيحا | B39: Taršīḥa | E39: Christian (Orthodox) | F39: C | G39: tʾīl | H39: Adeebi Yousif Khoury | I39: F | J39: Tr.11FC | K39: מספרת על ילדיה, היכן למדו. פתחו חנות. | L39: אין בין-דיניות. מימוש ق>ʾ. | M39: FALSE | N39: FALSE | P39: FALSE | Q39: FALSE | R39: FALSE | U39: FALSE | W39: FALSE | X39: FALSE | AK39: הגהה | AL39: עבר הגהה | AM39: תומר | AN39: Tr.11FC.R1 | AO39: 0.0017939815 | AP39: Yara Bshara | AQ39: 43009 | AR39: Tr.11M.R1(t) | AS39: =NOT(ISERROR(MATCH(A39,'Villages according to موسوعة ال'!C:C,0))) -> TRUE
A40: ترشيحا | B40: Taršīḥa | E40: Christian (Orthodox) | F40: C | G40: ṯʾīl | H40: Ghassān Gharzῡzi | I40: M | J40: Tr.12MC | K40: דאוד השומר הנוצרי ירה איש מוסלמי בטעות והרג אותו, יצאו שמועות שמוסלמים בתרשיחא רצו לנקום ולהרוג איש נוצרי, אך המוסלמים שמרו על הנוצרים מכל פגיעה, במידה ומישהו מוסלמי ירצה לפגוע בהם, והם חיו בסובלנות ביחד כל הזמן. | L40: כינוי חבור , substarte from aramiac: lammin (=lamman) , מימוש ق>ʾ. סיומת נקבה e-. ج = ž. | M40: FALSE | N40: FALSE | O40: -e | P40: FALSE | Q40: FALSE | R40: FALSE | S40: ž | T40: ʾ | U40: FALSE | W40: FALSE | X40: FALSE | Z40: hunne | AE40: badd | AI40: kān / čān | AK40: הגהה | AL40: אושר (אורי) | AM40: רבחי | AN40: Tr.12MC.R1 | AO40: 0.00068287037 | AP40: Layal Bshara | AQ40: 43009 | AR40: Tr.12MC.R1(t) | AS40: =NOT(ISERROR(MATCH(A40,'Villages according to موسوعة ال'!C:C,0))) -> TRUE
...

Sheet Texts
A3: U-Center | C3: Xl.3M.R1 | D3: kalb min liklāb ilmuʾrifīn | E3: unsplitt -CC ; stable CaCaCa in V1, V7 | F3: {=INDEX(Recordings!AK:AK, MATCH(C3, Recordings!AN:AN, 0))} -> הגהה | G3: אושר (אורי) | H3: לתעתק גם סיפור החתול דקה 08׳00
C4: Xl.4F.R1 | D4: ḥāmel ib-ʾabūki | E4: medial imāla | F4: תעתיק | G4: מאושר לתעתיק
C5: Rml.7FC.R1 | D5: sinʿa w-ʿam bibīʿu fī-ha | F5: {=INDEX(Recordings!AK:AK, MATCH(C5, Recordings!AN:AN, 0))} -> הגהה | G5: {=INDEX(Recordings!AL:AL, MATCH(C5, Recordings!AN:AN, 0))} -> עבר הגהה
C6: Ld.1FC.R1 | D6: xsāra hadōl mā yitʿallamū-šši, minʿallim-hon ʿa-ḥsāb-na | F6: {=INDEX(Recordings!AK:AK, MATCH(C6, Recordings!AN:AN, 0))} -> הגהה | G6: {=INDEX(Recordings!AL:AL, MATCH(C6, Recordings!AN:AN, 0))} -> עבר הגהה
C7: Jr.1MA.R1 | D7: kānu yžīn-o arman yaḥku turki | F7: {=INDEX(Recordings!AK:AK, MATCH(C7, Recordings!AN:AN, 0))} -> הגהה | G7: {=INDEX(Recordings!AL:AL, MATCH(C7, Recordings!AN:AN, 0))} -> אושר (אורי) | H7: אלא אם יימצא טקסט ארמני מתאים יותר
A9: U-North | C9: Nb.1M.R1 | D9: aʿžabatni bi-ššāreʿ w-šufthe | F9: {=INDEX(Recordings!AK:AK, MATCH(C9, Recordings!AN:AN, 0))} -> בקרה | G9: {=INDEX(Recordings!AL:AL, MATCH(C9, Recordings!AN:AN, 0))} -> בטיפול
B10: Nāblus | C10: Nb.3M.R1 | D10: ilʾaqzām ʿammālhon bištiġlu | F10: {=INDEX(Recordings!AK:AK, MATCH(C10, Recordings!AN:AN, 0))} -> בקרה | G10: {=INDEX(Recordings!AL:AL, MATCH(C10, Recordings!AN:AN, 0))} -> אושר (אורי)
C11: Ḥf.1FC.R1 | D11: w-yidillna iṭṭuruʾāt bi-lwaʿir ta-nūṣal | F11: {=INDEX(Recordings!AK:AK, MATCH(C11, Recordings!AN:AN, 0))} -> הגהה | G11: {=INDEX(Recordings!AL:AL, MATCH(C11, Recordings!AN:AN, 0))} -> עבר הגהה
C12: Ḥf.4MC.R1 | D12: axadu lkaleb w-saraʾū | F12: {=INDEX(Recordings!AK:AK, MATCH(C12, Recordings!AN:AN, 0))} -> הגהה | G12: {=INDEX(Recordings!AL:AL, MATCH(C12, Recordings!AN:AN, 0))} -> עבר הגהה
A14: R-North
C15: KM.1M.R1 | D15: rakkab-u ʿala ḏ̣ahr-u | E15: ṯqīl baqa | F15: {=INDEX(Recordings!AK:AK, MATCH(C15, Recordings!AN:AN, 0))} -> הגהה | G15: {=INDEX(Recordings!AL:AL, MATCH(C15, Recordings!AN:AN, 0))} -> אושר (אורי) | H15: קצר מאוד, להוסיף עוד קטע תעתיק
C16: Tr.2F.R1 | D16: ha-liḥṣān ha-lʾaddi ʿazīz | F16: {=INDEX(Recordings!AK:AK, MATCH(C16, Recordings!AN:AN, 0))} -> הגהה | G16: {=INDEX(Recordings!AL:AL, MATCH(C16, Recordings!AN:AN, 0))} -> אושר (אורי)
B17: Taršīḥa | C17: Tr.2F.R2 | D17: tiṣfīr | F17: {=INDEX(Recordings!AK:AK, MATCH(C17, Recordings!AN:AN, 0))} -> הגהה | G17: {=INDEX(Recordings!AL:AL, MATCH(C17, Recordings!AN:AN, 0))} -> עבר הגהה
C18: KS.1FC.R1 | D18: kubbit baṭāṭa | E18: ṯʾīl ; i~e# ; Silent h ; ant.pron ; intr. kān | F18: {=INDEX(Recordings!AK:AK, MATCH(C18, Recordings!AN:AN, 0))} -> בקרה | G18: {=INDEX(Recordings!AL:AL, MATCH(C18, Recordings!AN:AN, 0))} -> אושר (אורי) | H18: מחכה לתרגום
C19: Ġǧ.1F.R3 | D19: alġanmi - ṭayliʿīha tirǧa la-ḥāla | E19: non-diff. ; CayCaC ; CaCaC.CaCiC ; ay~ē | F19: {=INDEX(Recordings!AK:AK, MATCH(C19, Recordings!AN:AN, 0))} -> תעתיק | G19: {=INDEX(Recordings!AL:AL, MATCH(C19, Recordings!AN:AN, 0))} -> אושר (אורי)
B20: Birʿim | C20: Br.2MC.R1 | D20: mawʾif ḥariž min il-mawāʾif | F20: {=INDEX(Recordings!AK:AK, MATCH(C20, Recordings!AN:AN, 0))} -> בקרה | G20: {=INDEX(Recordings!AL:AL, MATCH(C20, Recordings!AN:AN, 0))} -> אושר (אורי) | H20: מחכה לתרגום
C21: KY.1FC.R1 | D21: walad maḥrūʾ nāʾeṣ aʿḍāʾ min žism-o | F21: {=INDEX(Recordings!AK:AK, MATCH(C21, Recordings!AN:AN, 0))} -> הגהה | G21: {=INDEX(Recordings!AL:AL, MATCH(C21, Recordings!AN:AN, 0))} -> אושר (אורי) | H21: מחכה לתרגום
B22: Faṣṣūṭa | C22: Fs.3MC.R1 | D22: Mṣallabt iddam | E22: w-glide | F22: {=INDEX(Recordings!AK:AK, MATCH(C22, Recordings!AN:AN, 0))} -> הגהה | G22: {=INDEX(Recordings!AL:AL, MATCH(C22, Recordings!AN:AN, 0))} -> אושר (אורי) | H22: קיים תרגום חלקי במאמר 2023
C23: Yr.1FD.R1 | D23: tʿallamet taṣmīm daxilay | F23: {=INDEX(Recordings!AK:AK, MATCH(C23, Recordings!AN:AN, 0))} -> הגהה | G23: {=INDEX(Recordings!AL:AL, MATCH(C23, Recordings!AN:AN, 0))} -> עבר הגהה
C24: Kb.1F.R1 | E24: סיפור מתחיל סביב 24:25 עד 29:20 | F24: תעתיק | G24: {=INDEX(Recordings!AL:AL, MATCH(C24, Recordings!AN:AN, 0))} -> מאושר לתעתיק | H24: מחכה לתעתיק
A26: R-Triangle | B26: Umm ilFaḥm | C26: UF.3F.R1 | D26: Mḥimmad itṣāwab ib-ʾīdu | F26: הגהה | G26: אושר (אורי) | H26: מחכה לתרגום
C27: ṬMṯ.1F.R1 | D27: ilyahudiyyāt yiḥtallēn iddār | F27: {=INDEX(Recordings!AK:AK, MATCH(C27, Recordings!AN:AN, 0))} -> הגהה | G27: {=INDEX(Recordings!AL:AL, MATCH(C27, Recordings!AN:AN, 0))} -> עבר הגהה
C28: BĠr.1F.R1 | D28: akalna mn izzād w-ilmiliḥ | F28: {=INDEX(Recordings!AK:AK, MATCH(C28, Recordings!AN:AN, 0))} -> תעתיק | G28: {=INDEX(Recordings!AL:AL, MATCH(C28, Recordings!AN:AN, 0))} -> אושר (אורי)
A30: R-Coast | C30: Fr.1F.R1 | D30: wikʿat minni lʿugá | F30: {=INDEX(Recordings!AK:AK, MATCH(C30, Recordings!AN:AN, 0))} -> תעתיק | G30: {=INDEX(Recordings!AL:AL, MATCH(C30, Recordings!AN:AN, 0))} -> אושר (אורי)
A32: R-Center | C32: ʿnt.3F.R1 | D32: izzalama barūdta fi čitfeh# / Innocent (CRPA 1805) | F32: {=INDEX(Recordings!AK:AK, MATCH(C32, Recordings!AN:AN, 0))} -> הגהה | G32: {=INDEX(Recordings!AL:AL, MATCH(C32, Recordings!AN:AN, 0))} -> בטיפול
C33: Lf.1M.R2 | D33: min ilʿēla ʿa-ṯāni ʿēle# (CRPA 2502) | F33: {=INDEX(Recordings!AK:AK, MATCH(C33, Recordings!AN:AN, 0))} -> הגהה | G33: {=INDEX(Recordings!AL:AL, MATCH(C33, Recordings!AN:AN, 0))} -> עבר הגהה
B34: Kaṭanna | C34: Kṭn.1F.R1 | D34: ḏ̣ayyaʿta la-lmiftāḥ lizġīr / Soldiers in pajamas (CRPA 3102) | F34: {=INDEX(Recordings!AK:AK, MATCH(C34, Recordings!AN:AN, 0))} -> הגהה | G34: אושר (אורי) | H34: מחכה לתרגום
B35: ilXaḏ̣ir | C35: Xḏ̣.2M.R1 | D35: lāzim ačayyil tačyīl | E35: narr.impt UCC a~e# -ču | F35: {=INDEX(Recordings!AK:AK, MATCH(C35, Recordings!AN:AN, 0))} -> הגהה | G35: אושר (אורי) | H35: מחכה לאוזן שנייה ותרגום
B36: Bēt Ǧāla | C36: BǦl.3M.R1 | D36: ibnat iFranklištayn | F36: {=INDEX(Recordings!AK:AK, MATCH(C36, Recordings!AN:AN, 0))} -> הגהה | G36: אושר (אורי)
B37: Bēt Nakūba | C37: BNk.1F.R1 | D37: Work arrangement (CRPA 2704) | F37: {=INDEX(Recordings!AK:AK, MATCH(C37, Recordings!AN:AN, 0))} -> הגהה | G37: {=INDEX(Recordings!AL:AL, MATCH(C37, Recordings!AN:AN, 0))} -> עבר הגהה
B38: Sinǧil | C38: Sn.1F.R2 | D38: iṭlub mir͜ min rabb-ak yiskī-k | F38: הגהה | G38: אושר (אורי) | H38: מחכה לאוזן שנייה ותרגום
C39: XB.1F.R4 | D39: Waking the dead (CRPA 8304) | F39: {=INDEX(Recordings!AK:AK, MATCH(C39, Recordings!AN:AN, 0))} -> הגהה | G39: {=INDEX(Recordings!AL:AL, MATCH(C39, Recordings!AN:AN, 0))} -> עבר הגהה
C40: XB.1F.R3 | F40: {=INDEX(Recordings!AK:AK, MATCH(C40, Recordings!AN:AN, 0))} -> תעתיק | G40: {=INDEX(Recordings!AL:AL, MATCH(C40, Recordings!AN:AN, 0))} -> בטיפול
C41: BF.2M.R1 | D41: bakat ʿinna baġla bēḏ̣a | F41: {=INDEX(Recordings!AK:AK, MATCH(C41, Recordings!AN:AN, 0))} -> הגהה | G41: {=INDEX(Recordings!AL:AL, MATCH(C41, Recordings!AN:AN, 0))} -> עבר הגהה
C42: WN.1F.R1 | D42: daxalt fi-ddukkōn w-kilt iḥmū-ni | E42: Push chain ā>ō => aw>ō>ū | F42: {=INDEX(Recordings!AK:AK, MATCH(C42, Recordings!AN:AN, 0))} -> הגהה | G42: {=INDEX(Recordings!AL:AL, MATCH(C42, Recordings!AN:AN, 0))} -> עבר הגהה
C43: Is.1F.R3 | D43: CRPA 1304 | F43: {=INDEX(Recordings!AK:AK, MATCH(C43, Recordings!AN:AN, 0))} -> הגהה | G43: {=INDEX(Recordings!AL:AL, MATCH(C43, Recordings!AN:AN, 0))} -> עבר הגהה
B44: Silwān | C44: Sl.3M.R1 | D44: dīč malʿūn wāldēn | E44: להמשיך עד סוף ההקלטה! | F44: {=INDEX(Recordings!AK:AK, MATCH(C44, Recordings!AN:AN, 0))} -> בקרה | G44: {=INDEX(Recordings!AL:AL, MATCH(C44, Recordings!AN:AN, 0))} -> עבר הגהה
C45: Sn.1F.R2 | D45: lēš ha-ččanna w-ʾačalna ʿrūk čirsanna | F45: {=INDEX(Recordings!AK:AK, MATCH(C45, Recordings!AN:AN, 0))} -> הגהה | G45: {=INDEX(Recordings!AL:AL, MATCH(C45, Recordings!AN:AN, 0))} -> אושר (אורי)
B46: Silbīt | C46: Sil.1F.R7 | D46: ana kīla w-il-a w-la-uxt-a kīle# | F46: {=INDEX(Recordings!AK:AK, MATCH(C46, Recordings!AN:AN, 0))} -> הגהה | G46: אושר (אורי)
A48: B-Galilee | B48: Ṭūba | C48: ṬZn.1FB.R1 | D48: bandōra | F48: {=INDEX(Recordings!AK:AK, MATCH(C48, Recordings!AN:AN, 0))} -> הגהה | G48: {=INDEX(Recordings!AL:AL, MATCH(C48, Recordings!AN:AN, 0))} -> עבר הגהה
...

Sheet Villages according to موسوعة ال
B1: תעתיק | C1: שם היישוב | D1: קוד | E1: הרכב האוכלוסיה | F1: האם יש לנו הקלטות? | G1: כמה? | H1: האם נבחרו לספר? | I1: כמה? | J1: הערות
A2: الجولان | B2: Maždal Šams | C2: مجدل شمس | D2: MŠ | E2: D (Golan) | F2: =IF(G2=0,"בכלל לא","כן") -> כן | G2: =COUNTIF(Recordings!A:A,C2) -> 2
B3: Masʿadi | C3: مسعدة | D3: Ms | E3: D (Golan) | F3: =IF(G3=0,"בכלל לא","כן") -> כן | G3: =COUNTIF(Recordings!A:A,C3) -> 4
B4: Ein Qiniyye | C4: عين قنية | D4: EQ | E4: D (Golan) | F4: =IF(G4=0,"בכלל לא","כן") -> כן | G4: =COUNTIF(Recordings!A:A,C4) -> 1
B5: Buqʿāṯa | C5: بقعاثا | D5: Bqṯ | E5: D (Golan) | F5: =IF(G5=0,"בכלל לא","כן") -> בכלל לא | G5: =COUNTIF(Recordings!A:A,C5) -> 0
A6: صفد | B6: ižŽišš | C6: الجش | D6: Žš | E6: C (Maronite, Melkite, Catholic?, Muslim) | F6: =IF(G6=0,"בכלל לא","כן") -> כן | G6: =COUNTIF(Recordings!A:A,C6) -> 1
B7: Ġaǧar | C7: غجر | D7: Gǧ | E7: Alawite | F7: =IF(G7=0,"בכלל לא","כן") -> כן | G7: =COUNTIF(Recordings!A:A,C7) -> 5
B8: ʿArab azZbēdāt | C8: عرب الزبيدات | D8: AZ | F8: =IF(G8=0,"בכלל לא","כן") -> כן | G8: =COUNTIF(Recordings!A:A,C8) -> 1
B9: Ḥurfēš | C9: حرفيش | D9: Ḥr | E9: D (Galilee), C (Melkite), Muslim (very few) | F9: =IF(G9=0,"בכלל לא","כן") -> בכלל לא | G9: =COUNTIF(Recordings!A:A,C9) -> 0 | U9: ʿArab alḤamdūn | V9: AḤ | W9: אין הקלטות בכלל
B10: arRīḥāniyya | C10: الريحانية | D10: Rḥ | E10: Circassian | F10: =IF(G10=0,"בכלל לא","כן") -> בכלל לא | G10: =COUNTIF(Recordings!A:A,C10) -> 0 | U10: ʿArab alMrēsāt | V10: AM | W10: אין הקלטות בכלל
B11: Ṭūba-azZanġariyya | C11: طوبا الزنغرية | D11: ṬZn | E11: B (Galilee) | F11: =IF(G11=0,"בכלל לא","כן") -> כן | G11: =COUNTIF(Recordings!A:A,C11) -> 6 | U11: ʿArab alĠawārna | V11: AĠ | W11: אין הקלטות בכלל
B12: Ṣafad | C12: صفد | D12: Ṣf | F12: =IF(G12=0,"בכלל לא","כן") -> בכלל לא | G12: =COUNTIF(Recordings!A:A,C12) -> 0 | U12: Arab alGēṭiyya | V12: AG | W12: אין הקלטות בכלל
B13: Kufur Birʿim | C13: كفر برعم | D13: Br | F13: =IF(G13=0,"בכלל לא","כן") -> כן | G13: =COUNTIF(Recordings!A:A,C13) -> 5
B14: alḤusēniyya | C14: الحسينية | D14: Ḥs | F14: =IF(G14=0,"בכלל לא","כן") -> בכלל לא | G14: =COUNTIF(Recordings!A:A,C14) -> 0
B15: ʿAkbara | C15: عكبرة | D15: Akb | E15: M | F15: =IF(G15=0,"בכלל לא","כן") -> בכלל לא | G15: =COUNTIF(Recordings!A:A,C15) -> 0 | J15: Includes population from Qadita. | U15: ʿArab alLhēb | V15: AL | W15: אין הקלטות בכלל
A16: عكا | B16: Abu Snān | C16: أبو سنان | D16: ASn | E16: D (Galilee), M, C (Orthodox, Melkite, Evangelical?) | F16: =IF(G16=0,"בכלל לא","כן") -> כן | G16: =COUNTIF(Recordings!A:A,C16) -> 4 | U16: ʿArab asSamniyya | V16: ASm | W16: אין הקלטות בכלל
B17: liBʿēni | C17: البعنة | D17: Bni | E17: M, C (Melkite, Orthodox), B (Galilee) | F17: =IF(G17=0,"בכלל לא","כן") -> בכלל לא | G17: =COUNTIF(Recordings!A:A,C17) -> 0 | U17: ʿArab aṣṢwēṭāt | V17: AṢ | W17: אין הקלטות בכלל
B18: ilBqēʿa | C18: البقيعة | D18: Bq | E18: D (Galilee), M, C (Orthodox, Melkite) | F18: =IF(G18=0,"בכלל לא","כן") -> כן | G18: =COUNTIF(Recordings!A:A,C18) -> 5 | U18: ʿArab alʿAmariyya | V18: AAm | W18: אין הקלטות בכלל
B19: Ždaydi-ilMaker | C19: جديدة-المكر | D19: ŽM | E19: M, C (Orthodox, Melkite) | F19: =IF(G19=0,"בכלל לא","כן") -> בכלל לא | G19: =COUNTIF(Recordings!A:A,C19) -> 0 | J19: Includes many displaced from surounding villages. | U19: ʿArab alGmērāt | V19: AGm | W19: אין הקלטות בכלל
B20: alḤusēniyya | C20: الحسينية | D20: Ḥs | E20: B (Galilee) | F20: =IF(G20=0,"בכלל לא","כן") -> בכלל לא | G20: =COUNTIF(Recordings!A:A,C20) -> 0 | U20: ʿArab alXawālid | V20: AX | W20: אין הקלטות בכלל
B21: irRāmi | C21: الرامة | D21: Rm | E21: D (Galilee), M, C (Orthodox, Melkite, Latin) | F21: =IF(G21=0,"בכלל לא","כן") -> כן | G21: =COUNTIF(Recordings!A:A,C21) -> 3 | J21: Includes most of the populatin from Iqriṯ & Birʿim. | U21: Ḥilf Ṭabbāš | V21: ḤṬ | W21: אין הקלטות בכלל
B22: išŠēx Dannūn | C22: الشيخ دنون | D22: ŠD | F22: =IF(G22=0,"בכלל לא","כן") -> בכלל לא | G22: =COUNTIF(Recordings!A:A,C22) -> 0 | U22: ʿArab alḤaǧāǧra | V22: AḤǧǧ | W22: אין הקלטות בכלל
C23: القبسي | D23: Qbs | E23: B (Galilee) | F23: =IF(G23=0,"בכלל לא","כן") -> בכלל לא | G23: =COUNTIF(Recordings!A:A,C23) -> 0 | U23: ʿArab alǦawāmīs | V23: AǦ | W23: אין הקלטות בכלל
B24: ačČammāna | C24: الكمانة | D24: Čm | E24: B (Galilee) | F24: =IF(G24=0,"בכלל לא","כן") -> בכלל לא | G24: =COUNTIF(Recordings!A:A,C24) -> 0 | U24: ʿArab alĠazzālīn | V24: AĠz | W24: אין הקלטות בכלל
B25: ilMazraʿa | C25: المزرعة | D25: Mz | E25: M | F25: =IF(G25=0,"בכלל לא","כן") -> בכלל לא | G25: =COUNTIF(Recordings!A:A,C25) -> 0 | U25: ʿArab alĠrīfāt | V25: AĠr | W25: אין הקלטות בכלל
B26: Bēt Žān | C26: بيت جان | D26: BŽ | E26: D (Galilee) | F26: =IF(G26=0,"בכלל לא","כן") -> בכלל לא | G26: =COUNTIF(Recordings!A:A,C26) -> 0 | U26: ʿArab alMazārīb | V26: AMz | W26: אין הקלטות בכלל
B27: Žūlis | C27: جولس | D27: Žl | E27: D (Galilee), M (very few) | F27: =IF(G27=0,"בכלל לא","כן") -> בכלל לא | G27: =COUNTIF(Recordings!A:A,C27) -> 0 | U27: ʿArab anNǧēdāt | V27: ANǧ | W27: אין הקלטות בכלל
B28: Dēr ilAsad | C28: دير الأسد | D28: DA | E28: M | F28: =IF(G28=0,"בכלל לא","כן") -> כן | G28: =COUNTIF(Recordings!A:A,C28) -> 1
B29: Dēr Ḥanna | C29: دير حنا | D29: DḤ | E29: M, C (Orthodox), B (Galilee) | F29: =IF(G29=0,"בכלל לא","כן") -> בכלל לא | G29: =COUNTIF(Recordings!A:A,C29) -> 0 | U29: ʿArab asSʿadiyya | V29: ASd | W29: אין הקלטות בכלל
B30: Rās ilĒn | C30: راس العين | D30: RE | E30: D (Galilee) | F30: =IF(G30=0,"בכלל לא","כן") -> בכלל לא | G30: =COUNTIF(Recordings!A:A,C30) -> 0 | U30: Manšiyyat izZibdi | V30: MZ | W30: אין הקלטות בכלל
B31: Sažūr | C31: ساجور | D31: Sž | E31: D (Galilee) | F31: =IF(G31=0,"בכלל לא","כן") -> בכלל לא | G31: =COUNTIF(Recordings!A:A,C31) -> 0 | U31: ʿArab adDalāyka | V31: AD | W31: אין הקלטות בכלל
B32: Saxnīn | C32: سخنين | D32: Sx | E32: M (large Sufi population), C (Orthodox, Melkite), B (Galilee) | F32: =IF(G32=0,"בכלל לא","כן") -> כן | G32: =COUNTIF(Recordings!A:A,C32) -> 1 | U32: ʿArab asSaʿāyda | V32: ASy | W32: אין הקלטות בכלל
B33: Šaʿab | C33: شعب | D33: Šb | E33: M, B (Galilee) | F33: =IF(G33=0,"בכלל לא","כן") -> בכלל לא | G33: =COUNTIF(Recordings!A:A,C33) -> 0 | J33: Majority of population displaced from neighbouring villages.
B34: Ṭamra | C34: طمرة | D34: Ṭmr | E34: M, B (Galilee) | F34: =IF(G34=0,"בכלל לא","כן") -> כן | G34: =COUNTIF(Recordings!A:A,C34) -> 1
B35: ʿArrābi | C35: عرابة | D35: Ar | E35: M, C (Melkite) | F35: =IF(G35=0,"בכלל לא","כן") -> כן | G35: =COUNTIF(Recordings!A:A,C35) -> 4
B36: ʿArab alʿArāmša | C36: عرب العرامشة | D36: AA | E36: B (Galilee) | F36: =IF(G36=0,"בכלל לא","כן") -> בכלל לא | G36: =COUNTIF(Recordings!A:A,C36) -> 0
B37: ʿArab asSawāʿid | C37: عرب السواعد | D37: AS | F37: =IF(G37=0,"בכלל לא","כן") -> בכלל לא | G37: =COUNTIF(Recordings!A:A,C37) -> 0
B38: ʿArab anNaʿīm | C38: عرب النعيم | D38: AN | E38: B (Galilee) | F38: =IF(G38=0,"בכלל לא","כן") -> בכלל לא | G38: =COUNTIF(Recordings!A:A,C38) -> 0
B39: ʿAkka | C39: عكا | D39: Ak | F39: =IF(G39=0,"בכלל לא","כן") -> כן | G39: =COUNTIF(Recordings!A:A,C39) -> 1
B40: ʿĒn ilAsad | C40: عين الأسد | D40: EA | F40: =IF(G40=0,"בכלל לא","כן") -> בכלל לא | G40: =COUNTIF(Recordings!A:A,C40) -> 0
...

Sheet Statistics
A1: כלל הקורפוס | E1: רשימת דוברים מלאה | F1: מגדר | H1: רשימת דוברים (בקרה/הגהה/תעתיק) | I1: מגדר | K1: מגדר הדוברים | L1: כמות
B2: בקרה | C2: =SUMIF(Recordings!AK:AK, B2, Recordings!AO:AO) -> 0.1384375 | E2: =IFERROR(__xludf.DUMMYFUNCTION("ARRAYFORMULA(LET(names, IFERROR(REGEXEXTRACT(Recordings!AN2:AN1402, ""^(.*)\.R""),""""), unique_names, SORT(UNIQUE(FILTER(names, names<>""""))), {unique_names, VLOOKUP(unique_names, {names, Recordings!I2:I1402}, 2, 0)}))"),"Ab.1M") -> Ab.1M | F2: =IFERROR(__xludf.DUMMYFUNCTION("""COMPUTED_VALUE"""),"M") -> M | H2: =IFERROR(__xludf.DUMMYFUNCTION("ARRAYFORMULA(LET(names, IFERROR(REGEXEXTRACT(Recordings!AN2:AN1402, ""^(.*)\.R""),""""), designations, Recordings!AK2:AK1402, target_list, SORT(UNIQUE(FILTER(names, REGEXMATCH(designations, ""^(בקרה|תעתיק|הגהה)$"")))), {target_list, VLOOKUP(target_list, {"&"names, Recordings!I2:I1402}, 2, 0)}))"),"") | K2: זכר | L2: =COUNTIF(I3:I1402, "M") -> 138
B3: דקדוק | C3: =SUMIF(Recordings!AK:AK, B3, Recordings!AO:AO) -> 0.625625 | E3: =IFERROR(__xludf.DUMMYFUNCTION("""COMPUTED_VALUE"""),"AČ.1FB") -> AČ.1FB | F3: =IFERROR(__xludf.DUMMYFUNCTION("""COMPUTED_VALUE"""),"F") -> F | H3: =IFERROR(__xludf.DUMMYFUNCTION("""COMPUTED_VALUE"""),"Ab.1M") -> Ab.1M | I3: =IFERROR(__xludf.DUMMYFUNCTION("""COMPUTED_VALUE"""),"M") -> M | K3: נקבה | L3: =COUNTIF(I3:I1402, "F") -> 126
B4: הגהה | C4: =SUMIF(Recordings!AK:AK, B4, Recordings!AO:AO) -> 0.80769676 | E4: =IFERROR(__xludf.DUMMYFUNCTION("""COMPUTED_VALUE"""),"AD.1F") -> AD.1F | F4: =IFERROR(__xludf.DUMMYFUNCTION("""COMPUTED_VALUE"""),"F") -> F | H4: =IFERROR(__xludf.DUMMYFUNCTION("""COMPUTED_VALUE"""),"AČ.1FB") -> AČ.1FB | I4: =IFERROR(__xludf.DUMMYFUNCTION("""COMPUTED_VALUE"""),"F") -> F | K4: סה״כ | L4: =SUM(L2:L3) -> 264
B5: זבל | C5: =SUMIF(Recordings!AK:AK, B5, Recordings!AO:AO) -> 0.09556713 | E5: =IFERROR(__xludf.DUMMYFUNCTION("""COMPUTED_VALUE"""),"AD.2F") -> AD.2F | F5: =IFERROR(__xludf.DUMMYFUNCTION("""COMPUTED_VALUE"""),"F") -> F | H5: =IFERROR(__xludf.DUMMYFUNCTION("""COMPUTED_VALUE"""),"AD.1F") -> AD.1F | I5: =IFERROR(__xludf.DUMMYFUNCTION("""COMPUTED_VALUE"""),"F") -> F
B6: תעתיק | C6: =SUMIF(Recordings!AK:AK, B6, Recordings!AO:AO) -> 0.74886574 | E6: =IFERROR(__xludf.DUMMYFUNCTION("""COMPUTED_VALUE"""),"AD.3M") -> AD.3M | F6: =IFERROR(__xludf.DUMMYFUNCTION("""COMPUTED_VALUE"""),"M") -> M | H6: =IFERROR(__xludf.DUMMYFUNCTION("""COMPUTED_VALUE"""),"AD.5F") -> AD.5F | I6: =IFERROR(__xludf.DUMMYFUNCTION("""COMPUTED_VALUE"""),"F") -> F | K6: מגדר הדוברים (רשימה מלאה) | L6: כמות
B7: ריק | C7: =SUMIF(Recordings!AK:AK, "", Recordings!AO:AO) -> 1.2047569 | E7: =IFERROR(__xludf.DUMMYFUNCTION("""COMPUTED_VALUE"""),"AD.4M") -> AD.4M | F7: =IFERROR(__xludf.DUMMYFUNCTION("""COMPUTED_VALUE"""),"M") -> M | H7: =IFERROR(__xludf.DUMMYFUNCTION("""COMPUTED_VALUE"""),"AĠ.1M") -> AĠ.1M | I7: =IFERROR(__xludf.DUMMYFUNCTION("""COMPUTED_VALUE"""),"M") -> M | K7: זכר | L7: =COUNTIF(F1:F1402, "M") -> 254
B8: סה״כ | C8: =SUM(C2:C7) -> 3.6209491 | E8: =IFERROR(__xludf.DUMMYFUNCTION("""COMPUTED_VALUE"""),"AD.5F") -> AD.5F | F8: =IFERROR(__xludf.DUMMYFUNCTION("""COMPUTED_VALUE"""),"F") -> F | H8: =IFERROR(__xludf.DUMMYFUNCTION("""COMPUTED_VALUE"""),"AĠ.2M") -> AĠ.2M | I8: =IFERROR(__xludf.DUMMYFUNCTION("""COMPUTED_VALUE"""),"M") -> M | K8: נקבה | L8: =COUNTIF(F1:F1402, "F") -> 220
E9: =IFERROR(__xludf.DUMMYFUNCTION("""COMPUTED_VALUE"""),"AD.6M") -> AD.6M | F9: =IFERROR(__xludf.DUMMYFUNCTION("""COMPUTED_VALUE"""),"M") -> M | H9: =IFERROR(__xludf.DUMMYFUNCTION("""COMPUTED_VALUE"""),"AĠ.4M") -> AĠ.4M | I9: =IFERROR(__xludf.DUMMYFUNCTION("""COMPUTED_VALUE"""),"M") -> M | K9: סה״כ | L9: =SUM(L7:L8) -> 474
E10: =IFERROR(__xludf.DUMMYFUNCTION("""COMPUTED_VALUE"""),"AD.7F") -> AD.7F | F10: =IFERROR(__xludf.DUMMYFUNCTION("""COMPUTED_VALUE"""),"F") -> F | H10: =IFERROR(__xludf.DUMMYFUNCTION("""COMPUTED_VALUE"""),"AĠ.5M") -> AĠ.5M | I10: =IFERROR(__xludf.DUMMYFUNCTION("""COMPUTED_VALUE"""),"M") -> M
A11: עיבוד משמעותי | E11: =IFERROR(__xludf.DUMMYFUNCTION("""COMPUTED_VALUE"""),"AĠ.10F") -> AĠ.10F | F11: =IFERROR(__xludf.DUMMYFUNCTION("""COMPUTED_VALUE"""),"F") -> F | H11: =IFERROR(__xludf.DUMMYFUNCTION("""COMPUTED_VALUE"""),"AǦh.1MB") -> AǦh.1MB | I11: =IFERROR(__xludf.DUMMYFUNCTION("""COMPUTED_VALUE"""),"M") -> M
B12: בקרה | C12: =SUMIF(Recordings!AK:AK, B2, Recordings!AO:AO) -> 0.1384375 | E12: =IFERROR(__xludf.DUMMYFUNCTION("""COMPUTED_VALUE"""),"AĠ.11M") -> AĠ.11M | F12: =IFERROR(__xludf.DUMMYFUNCTION("""COMPUTED_VALUE"""),"M") -> M | H12: =IFERROR(__xludf.DUMMYFUNCTION("""COMPUTED_VALUE"""),"AḤ.1FB") -> AḤ.1FB | I12: =IFERROR(__xludf.DUMMYFUNCTION("""COMPUTED_VALUE"""),"F") -> F
B13: הגהה | C13: =SUMIF(Recordings!AK:AK, B4, Recordings!AO:AO) -> 0.80769676 | E13: =IFERROR(__xludf.DUMMYFUNCTION("""COMPUTED_VALUE"""),"AĠ.12F") -> AĠ.12F | F13: =IFERROR(__xludf.DUMMYFUNCTION("""COMPUTED_VALUE"""),"F") -> F | H13: =IFERROR(__xludf.DUMMYFUNCTION("""COMPUTED_VALUE"""),"AḤǧ.1MB") -> AḤǧ.1MB | I13: =IFERROR(__xludf.DUMMYFUNCTION("""COMPUTED_VALUE"""),"M") -> M
B14: תעתיק | C14: =SUMIF(Recordings!AK:AK, B6, Recordings!AO:AO) -> 0.74886574 | E14: =IFERROR(__xludf.DUMMYFUNCTION("""COMPUTED_VALUE"""),"AĠ.13F") -> AĠ.13F | F14: =IFERROR(__xludf.DUMMYFUNCTION("""COMPUTED_VALUE"""),"F") -> F | H14: =IFERROR(__xludf.DUMMYFUNCTION("""COMPUTED_VALUE"""),"Arb.2M") -> Arb.2M | I14: =IFERROR(__xludf.DUMMYFUNCTION("""COMPUTED_VALUE"""),"M") -> M
B15: סה״כ | C15: =SUM(C12:C14) -> 1.695 | E15: =IFERROR(__xludf.DUMMYFUNCTION("""COMPUTED_VALUE"""),"AĠ.14F") -> AĠ.14F | F15: =IFERROR(__xludf.DUMMYFUNCTION("""COMPUTED_VALUE"""),"F") -> F | H15: =IFERROR(__xludf.DUMMYFUNCTION("""COMPUTED_VALUE"""),"Arḥ.2F") -> Arḥ.2F | I15: =IFERROR(__xludf.DUMMYFUNCTION("""COMPUTED_VALUE"""),"F") -> F
E16: =IFERROR(__xludf.DUMMYFUNCTION("""COMPUTED_VALUE"""),"AĠ.1M") -> AĠ.1M | F16: =IFERROR(__xludf.DUMMYFUNCTION("""COMPUTED_VALUE"""),"M") -> M | H16: =IFERROR(__xludf.DUMMYFUNCTION("""COMPUTED_VALUE"""),"Arr.1F") -> Arr.1F | I16: =IFERROR(__xludf.DUMMYFUNCTION("""COMPUTED_VALUE"""),"F") -> F
E17: =IFERROR(__xludf.DUMMYFUNCTION("""COMPUTED_VALUE"""),"AĠ.2M") -> AĠ.2M | F17: =IFERROR(__xludf.DUMMYFUNCTION("""COMPUTED_VALUE"""),"M") -> M | H17: =IFERROR(__xludf.DUMMYFUNCTION("""COMPUTED_VALUE"""),"Arš.1MB") -> Arš.1MB | I17: =IFERROR(__xludf.DUMMYFUNCTION("""COMPUTED_VALUE"""),"M") -> M
E18: =IFERROR(__xludf.DUMMYFUNCTION("""COMPUTED_VALUE"""),"AĠ.3M") -> AĠ.3M | F18: =IFERROR(__xludf.DUMMYFUNCTION("""COMPUTED_VALUE"""),"M") -> M | H18: =IFERROR(__xludf.DUMMYFUNCTION("""COMPUTED_VALUE"""),"AŠ.1MB") -> AŠ.1MB | I18: =IFERROR(__xludf.DUMMYFUNCTION("""COMPUTED_VALUE"""),"M") -> M
A19: לא עובד | E19: =IFERROR(__xludf.DUMMYFUNCTION("""COMPUTED_VALUE"""),"AĠ.4M") -> AĠ.4M | F19: =IFERROR(__xludf.DUMMYFUNCTION("""COMPUTED_VALUE"""),"M") -> M | H19: =IFERROR(__xludf.DUMMYFUNCTION("""COMPUTED_VALUE"""),"AŠ.3MB") -> AŠ.3MB | I19: =IFERROR(__xludf.DUMMYFUNCTION("""COMPUTED_VALUE"""),"M") -> M
B20: זבל | C20: =SUMIF(Recordings!AK:AK, B20, Recordings!AO:AO) -> 0.09556713 | E20: =IFERROR(__xludf.DUMMYFUNCTION("""COMPUTED_VALUE"""),"AĠ.5M") -> AĠ.5M | F20: =IFERROR(__xludf.DUMMYFUNCTION("""COMPUTED_VALUE"""),"M") -> M | H20: =IFERROR(__xludf.DUMMYFUNCTION("""COMPUTED_VALUE"""),"ASn.1MC") -> ASn.1MC | I20: =IFERROR(__xludf.DUMMYFUNCTION("""COMPUTED_VALUE"""),"M") -> M
B21: ריק | C21: =SUMIF(Recordings!AK:AK, "", Recordings!AO:AO) -> 1.2047569 | E21: =IFERROR(__xludf.DUMMYFUNCTION("""COMPUTED_VALUE"""),"AĠ.6F") -> AĠ.6F | F21: =IFERROR(__xludf.DUMMYFUNCTION("""COMPUTED_VALUE"""),"F") -> F | H21: =IFERROR(__xludf.DUMMYFUNCTION("""COMPUTED_VALUE"""),"ASn.2FC") -> ASn.2FC | I21: =IFERROR(__xludf.DUMMYFUNCTION("""COMPUTED_VALUE"""),"F") -> F
B22: סה״כ | C22: =SUM(C17:C21) -> 1.3003241 | E22: =IFERROR(__xludf.DUMMYFUNCTION("""COMPUTED_VALUE"""),"AĠ.7F") -> AĠ.7F | F22: =IFERROR(__xludf.DUMMYFUNCTION("""COMPUTED_VALUE"""),"F") -> F | H22: =IFERROR(__xludf.DUMMYFUNCTION("""COMPUTED_VALUE"""),"AZ.1MB") -> AZ.1MB | I22: =IFERROR(__xludf.DUMMYFUNCTION("""COMPUTED_VALUE"""),"M") -> M
E23: =IFERROR(__xludf.DUMMYFUNCTION("""COMPUTED_VALUE"""),"AĠ.8F") -> AĠ.8F | F23: =IFERROR(__xludf.DUMMYFUNCTION("""COMPUTED_VALUE"""),"F") -> F | H23: =IFERROR(__xludf.DUMMYFUNCTION("""COMPUTED_VALUE"""),"Bd.1F") -> Bd.1F | I23: =IFERROR(__xludf.DUMMYFUNCTION("""COMPUTED_VALUE"""),"F") -> F
A24: יחסים בין חומר שעובד לכזה שלא | E24: =IFERROR(__xludf.DUMMYFUNCTION("""COMPUTED_VALUE"""),"AĠ.9F") -> AĠ.9F | F24: =IFERROR(__xludf.DUMMYFUNCTION("""COMPUTED_VALUE"""),"F") -> F | H24: =IFERROR(__xludf.DUMMYFUNCTION("""COMPUTED_VALUE"""),"BD.3F") -> BD.3F | I24: =IFERROR(__xludf.DUMMYFUNCTION("""COMPUTED_VALUE"""),"F") -> F
B25: עובד | C25: =C7 -> 1.2047569 | E25: =IFERROR(__xludf.DUMMYFUNCTION("""COMPUTED_VALUE"""),"AǦh.1MB") -> AǦh.1MB | F25: =IFERROR(__xludf.DUMMYFUNCTION("""COMPUTED_VALUE"""),"M") -> M | H25: =IFERROR(__xludf.DUMMYFUNCTION("""COMPUTED_VALUE"""),"BD.5M") -> BD.5M | I25: =IFERROR(__xludf.DUMMYFUNCTION("""COMPUTED_VALUE"""),"M") -> M
B26: לא עובד | C26: =C15 -> 1.695 | E26: =IFERROR(__xludf.DUMMYFUNCTION("""COMPUTED_VALUE"""),"AǦh.2MB") -> AǦh.2MB | F26: =IFERROR(__xludf.DUMMYFUNCTION("""COMPUTED_VALUE"""),"M") -> M | H26: =IFERROR(__xludf.DUMMYFUNCTION("""COMPUTED_VALUE"""),"BD.6M") -> BD.6M | I26: =IFERROR(__xludf.DUMMYFUNCTION("""COMPUTED_VALUE"""),"M") -> M
E27: =IFERROR(__xludf.DUMMYFUNCTION("""COMPUTED_VALUE"""),"AǦh.3MB") -> AǦh.3MB | F27: =IFERROR(__xludf.DUMMYFUNCTION("""COMPUTED_VALUE"""),"M") -> M | H27: =IFERROR(__xludf.DUMMYFUNCTION("""COMPUTED_VALUE"""),"BF.1M") -> BF.1M | I27: =IFERROR(__xludf.DUMMYFUNCTION("""COMPUTED_VALUE"""),"M") -> M
A28: כמה יישובים מיוצגים? | E28: =IFERROR(__xludf.DUMMYFUNCTION("""COMPUTED_VALUE"""),"AǦh.4MB") -> AǦh.4MB | F28: =IFERROR(__xludf.DUMMYFUNCTION("""COMPUTED_VALUE"""),"M") -> M | H28: =IFERROR(__xludf.DUMMYFUNCTION("""COMPUTED_VALUE"""),"BF.2M") -> BF.2M | I28: =IFERROR(__xludf.DUMMYFUNCTION("""COMPUTED_VALUE"""),"M") -> M
B29: מכמה יישובים יש הקלטות | C29: =IFERROR(__xludf.DUMMYFUNCTION("COUNTUNIQUE(FILTER(TRIM(Recordings!A2:A1402), Recordings!A2:A1402<>"""", TRIM(Recordings!A2:A1402)<>""""))"),128.0) -> 128 | E29: =IFERROR(__xludf.DUMMYFUNCTION("""COMPUTED_VALUE"""),"AǦh.5MB") -> AǦh.5MB | F29: =IFERROR(__xludf.DUMMYFUNCTION("""COMPUTED_VALUE"""),"M") -> M | H29: =IFERROR(__xludf.DUMMYFUNCTION("""COMPUTED_VALUE"""),"BF.3F") -> BF.3F | I29: =IFERROR(__xludf.DUMMYFUNCTION("""COMPUTED_VALUE"""),"F") -> F
E30: =IFERROR(__xludf.DUMMYFUNCTION("""COMPUTED_VALUE"""),"AǦh.6MB") -> AǦh.6MB | F30: =IFERROR(__xludf.DUMMYFUNCTION("""COMPUTED_VALUE"""),"M") -> M | H30: =IFERROR(__xludf.DUMMYFUNCTION("""COMPUTED_VALUE"""),"BǦb.1M") -> BǦb.1M | I30: =IFERROR(__xludf.DUMMYFUNCTION("""COMPUTED_VALUE"""),"M") -> M
E31: =IFERROR(__xludf.DUMMYFUNCTION("""COMPUTED_VALUE"""),"AḤ.1FB") -> AḤ.1FB | F31: =IFERROR(__xludf.DUMMYFUNCTION("""COMPUTED_VALUE"""),"F") -> F | H31: =IFERROR(__xludf.DUMMYFUNCTION("""COMPUTED_VALUE"""),"BǦl.2F") -> BǦl.2F | I31: =IFERROR(__xludf.DUMMYFUNCTION("""COMPUTED_VALUE"""),"F") -> F
A32: ייצוג קהילות/דתות (WIP) | E32: =IFERROR(__xludf.DUMMYFUNCTION("""COMPUTED_VALUE"""),"AḤǧ.1MB") -> AḤǧ.1MB | F32: =IFERROR(__xludf.DUMMYFUNCTION("""COMPUTED_VALUE"""),"M") -> M | H32: =IFERROR(__xludf.DUMMYFUNCTION("""COMPUTED_VALUE"""),"BǦl.2M") -> BǦl.2M | I32: =IFERROR(__xludf.DUMMYFUNCTION("""COMPUTED_VALUE"""),"M") -> M
B33: Druze (Golan) | C33: =COUNTIF(Recordings!E:E, B33) -> 4 | E33: =IFERROR(__xludf.DUMMYFUNCTION("""COMPUTED_VALUE"""),"Ak.1M") -> Ak.1M | F33: =IFERROR(__xludf.DUMMYFUNCTION("""COMPUTED_VALUE"""),"M") -> M | H33: =IFERROR(__xludf.DUMMYFUNCTION("""COMPUTED_VALUE"""),"BǦl.3M") -> BǦl.3M | I33: =IFERROR(__xludf.DUMMYFUNCTION("""COMPUTED_VALUE"""),"M") -> M
B34: Alawite | C34: =COUNTIF(Recordings!E:E, B34) -> 1 | E34: =IFERROR(__xludf.DUMMYFUNCTION("""COMPUTED_VALUE"""),"Arb.1M") -> Arb.1M | F34: =IFERROR(__xludf.DUMMYFUNCTION("""COMPUTED_VALUE"""),"M") -> M | H34: =IFERROR(__xludf.DUMMYFUNCTION("""COMPUTED_VALUE"""),"BǦl.5M") -> BǦl.5M | I34: =IFERROR(__xludf.DUMMYFUNCTION("""COMPUTED_VALUE"""),"M") -> M
B35: Christian (Catholic) | C35: =COUNTIF(Recordings!E:E, B35) -> 23 | E35: =IFERROR(__xludf.DUMMYFUNCTION("""COMPUTED_VALUE"""),"Arb.2M") -> Arb.2M | F35: =IFERROR(__xludf.DUMMYFUNCTION("""COMPUTED_VALUE"""),"M") -> M | H35: =IFERROR(__xludf.DUMMYFUNCTION("""COMPUTED_VALUE"""),"BǦl.5MC") -> BǦl.5MC | I35: =IFERROR(__xludf.DUMMYFUNCTION("""COMPUTED_VALUE"""),"F") -> F
B36: Christian (Maronite) | C36: =COUNTIF(Recordings!E:E, B36) -> 12 | E36: =IFERROR(__xludf.DUMMYFUNCTION("""COMPUTED_VALUE"""),"Arb.3F") -> Arb.3F | F36: =IFERROR(__xludf.DUMMYFUNCTION("""COMPUTED_VALUE"""),"F") -> F | H36: =IFERROR(__xludf.DUMMYFUNCTION("""COMPUTED_VALUE"""),"BǦl.8M") -> BǦl.8M | I36: =IFERROR(__xludf.DUMMYFUNCTION("""COMPUTED_VALUE"""),"M") -> M
B37: Muslim | C37: =COUNTIF(Recordings!E:E, B37) -> 11 | E37: =IFERROR(__xludf.DUMMYFUNCTION("""COMPUTED_VALUE"""),"Arḥ.1F") -> Arḥ.1F | F37: =IFERROR(__xludf.DUMMYFUNCTION("""COMPUTED_VALUE"""),"F") -> F | H37: =IFERROR(__xludf.DUMMYFUNCTION("""COMPUTED_VALUE"""),"BĠr.1F") -> BĠr.1F | I37: =IFERROR(__xludf.DUMMYFUNCTION("""COMPUTED_VALUE"""),"F") -> F
B38: Christian (Orthodox) | C38: =COUNTIF(Recordings!E:E, B38) -> 32 | E38: =IFERROR(__xludf.DUMMYFUNCTION("""COMPUTED_VALUE"""),"Arḥ.2F") -> Arḥ.2F | F38: =IFERROR(__xludf.DUMMYFUNCTION("""COMPUTED_VALUE"""),"F") -> F | H38: =IFERROR(__xludf.DUMMYFUNCTION("""COMPUTED_VALUE"""),"BI.2F") -> BI.2F | I38: =IFERROR(__xludf.DUMMYFUNCTION("""COMPUTED_VALUE"""),"F") -> F
B39: Druze (Galilee) | C39: =COUNTIF(Recordings!E:E, B39) -> 16 | E39: =IFERROR(__xludf.DUMMYFUNCTION("""COMPUTED_VALUE"""),"Arr.1F") -> Arr.1F | F39: =IFERROR(__xludf.DUMMYFUNCTION("""COMPUTED_VALUE"""),"F") -> F | H39: =IFERROR(__xludf.DUMMYFUNCTION("""COMPUTED_VALUE"""),"BI.4F") -> BI.4F | I39: =IFERROR(__xludf.DUMMYFUNCTION("""COMPUTED_VALUE"""),"F") -> F
B40: Bedouin (Galilee) | C40: =COUNTIF(Recordings!E:E, B40) -> 14 | E40: =IFERROR(__xludf.DUMMYFUNCTION("""COMPUTED_VALUE"""),"Arš.1MB") -> Arš.1MB | F40: =IFERROR(__xludf.DUMMYFUNCTION("""COMPUTED_VALUE"""),"M") -> M | H40: =IFERROR(__xludf.DUMMYFUNCTION("""COMPUTED_VALUE"""),"BI.5M") -> BI.5M | I40: =IFERROR(__xludf.DUMMYFUNCTION("""COMPUTED_VALUE"""),"M") -> M
...
